<?xml version="1.0"?>
<robot name="my_robot">


  <material name="grey">
    <color rgba="0.7 0.7 0.7 1"/>
  </material>

  <material name="green">
    <color rgba="0 0.6 0 1"/>
  </material>

  <material name="white">
    <color rgba="1 1 1 1"/>
  </material>



  <link name="base_link">
    <visual>
      <geometry>
        <box size="0.6 0.4 0.2"/>
      </geometry>
      <origin xyz="0 0 0" rpy="0 0 0"/>
      <material name="green"/>
    </visual>
    <collision>
      <geometry>
        <box size="0.6 0.4 0.2"/>
      </geometry>
      <origin xyz="0 0 0" rpy="0 0 0"/>
    </collision>
    <inertial>
      <mass value="5.0"/>
      <inertia ixx="0.1" ixy="0.0" ixz="0.0"
               iyy="0.1" iyz="0.0"
               izz="0.1"/>
    </inertial>
  </link>

  <link name="base_footprint"/>

  <joint name="base_base_footprint" type="fixed">
    <parent link="base_link"/>
    <child link="base_footprint"/>
    <origin xyz="0 0 0.1" rpy="0 0 0"/>
  </joint>


  <joint name="base_lidar_joint" type="fixed">
    <parent link="base_link"/>
    <child link="lidar"/>
    <origin xyz="0.2 0 0.125" rpy="0 0 0"/>
  </joint>

  <link name="lidar">
    <visual>
      <geometry>
        <cylinder radius="0.05" length="0.04"/>
      </geometry>
      <material name="white"/>
    </visual>
    <collision>
      <geometry>
        <cylinder radius="0.05" length="0.04"/>
      </geometry>
    </collision>
    <inertial>
      <mass value="0.1"/>
      <inertia ixx="0.0001" ixy="0.0" ixz="0.0"
              iyy="0.0001" iyz="0.0"
              izz="0.0001"/>
    </inertial>

  </link>

      <gazebo reference="lidar">
        <material>Gazebo/Red</material>
        <sensor name="laser" type="ray">
            <pose> 0 0 0 0 0 0 </pose>
            <visualize>true</visualize>
            <update_rate>10</update_rate>
            <ray>
                <scan>
                    <horizontal>
                        <samples>360</samples>
                        <min_angle>-3.14</min_angle>
                        <max_angle>3.14</max_angle>
                    </horizontal>
                </scan>
                <range>
                    <min>0.3</min>
                    <max>12</max>
                </range>
            </ray>
            <plugin name="laser_controller" filename="libgazebo_ros_ray_sensor.so">
                <ros>
                    <argument>~/out:=scan</argument>
                </ros>
                <output_type>sensor_msgs/LaserScan</output_type>
                <frame_name>lidar</frame_name>
            </plugin>
        </sensor>
    </gazebo>

  <joint name="left_wheel_joint" type="continuous">
    <parent link="base_link"/>
    <child link="left_wheel"/>
    <origin xyz="-0.15 0.225 0" rpy="0 0 0"/>
    <axis xyz="0 1 0"/>
    <dynamics damping="0.1" friction="0.0"/>
  </joint>

  <link name="left_wheel">
    <visual>
      <geometry>
        <cylinder radius="0.1" length="0.05"/>
      </geometry>
      <origin xyz="0 0 0" rpy="1.57 0 0"/>
      <material name="grey"/>
    </visual>
    <collision>
      <geometry>
        <cylinder radius="0.1" length="0.05"/>
      </geometry>
      <origin xyz="0 0 0" rpy="1.57 0 0"/>
      <surface>
        <friction>
          <ode>
            <mu>1.0</mu>
            <mu2>1.0</mu2>
            <slip1>0.1</slip1>
            <slip2>0.1</slip2>
          </ode>
        </friction>
      </surface>
    </collision>
    <inertial>
      <mass value="1.0"/>
      <inertia ixx="0.005" ixy="0.0" ixz="0.0"
               iyy="0.005" iyz="0.0"
               izz="0.005"/>
    </inertial>
  </link>

<transmission name="left_wheel_trans">
  <type>transmission_interface/SimpleTransmission</type>
  <joint name="left_wheel_joint">
    <hardwareInterface>hardware_interface/velocity</hardwareInterface>
  </joint>
  <actuator name="left_motor">
    <mechanicalReduction>1</mechanicalReduction>
  </actuator>
</transmission>

  <joint name="right_wheel_joint" type="continuous">
    <parent link="base_link"/>
    <child link="right_wheel"/>
    <origin xyz="-0.15 -0.225 0" rpy="0 0 0"/>
    <axis xyz="0 1 0"/>
    <dynamics damping="0.1" friction="0.0"/>
  </joint>

  <link name="right_wheel">
    <visual>
      <geometry>
        <cylinder radius="0.1" length="0.05"/>
      </geometry>
      <origin xyz="0 0 0" rpy="1.57 0 0"/>
      <material name="grey"/>
    </visual>
    <collision>
      <geometry>
        <cylinder radius="0.1" length="0.05"/>
      </geometry>
      <origin xyz="0 0 0" rpy="1.57 0 0"/>
      <surface>
        <friction>
          <ode>
            <mu>1.0</mu>
            <mu2>1.0</mu2>
            <slip1>0.1</slip1>
            <slip2>0.1</slip2>
          </ode>
        </friction>
      </surface>
    </collision>
    <inertial>
      <mass value="1.0"/>
      <inertia ixx="0.005" ixy="0.0" ixz="0.0"
               iyy="0.005" iyz="0.0"
               izz="0.005"/>
    </inertial>
  </link>

<transmission name="right_wheel_trans">
  <type>transmission_interface/SimpleTransmission</type>
  <joint name="right_wheel_joint">
    <hardwareInterface>hardware_interface/velocity</hardwareInterface>
  </joint>
  <actuator name="right_motor">
    <mechanicalReduction>1</mechanicalReduction>
  </actuator>
</transmission>


  <joint name="caster_wheel_joint" type="fixed">
    <parent link="base_link"/>
    <child link="caster_wheel"/>
    <origin xyz="0.2 0 -0.05" rpy="0 0 0"/>
  </joint>

  <link name="caster_wheel">
    <visual>
      <geometry>
        <sphere radius="0.05"/>
      </geometry>
      <origin xyz="0 0 0" rpy="0 0 0"/>
      <material name="grey"/>
    </visual>
    <collision>
      <geometry>
        <sphere radius="0.05"/>
      </geometry>
      <surface>
        <friction>
          <ode>
            <mu>1.0</mu>
            <mu2>1.0</mu2>
          </ode>
        </friction>
      </surface>
    </collision>
    <inertial>
      <mass value="0.5"/>
      <inertia ixx="0.001" ixy="0.0" ixz="0.0"
              iyy="0.001" iyz="0.0"
              izz="0.001"/>
    </inertial>
  </link>

  <ros2_control name="GazeboSystem" type="system">
    <hardware>
      <plugin>gazebo_ros2_control/GazeboSystem</plugin>
    </hardware>
    <joint name="left_wheel_joint">
      <command_interface name="velocity"/>
      <state_interface name="position"/>
      <state_interface name="velocity"/>
    </joint>
    <joint name="right_wheel_joint">
      <command_interface name="velocity"/>
      <state_interface name="position"/>
      <state_interface name="velocity"/>
    </joint>
  </ros2_control>


  <gazebo>
    <static>false</static>
    <plugin name="gazebo_ros2_control" filename="libgazebo_ros2_control.so">
      <parameters>$(find main_logic_controller)/config/my_controllers.yaml</parameters>
    </plugin>
  </gazebo>
  
  <gazebo reference="base_link">
    <material>Gazebo/Green</material>
  </gazebo>
  <gazebo reference="left_wheel">
    <material>Gazebo/Grey</material>
  </gazebo>
  <gazebo reference="right_wheel">
    <material>Gazebo/Grey</material>
  </gazebo>
  <gazebo reference="lidar">
    <material>Gazebo/White</material>
  </gazebo>
</robot>
